<?xml version="1.0" encoding="UTF-8"?>
<!-- Generated by org.testng.reporters.JUnitXMLReporter -->
<testsuite hostname="EMB-BAN-168" ignored="4" name="Default test" tests="1" failures="1" timestamp="20 Jul 2018 13:06:29 GMT" time="51.007" errors="0">
  <testcase name="coverStoryOTPLogin" time="17.651" classname="com.qa.testcases.TestCswLogin">
    <failure type="java.lang.AssertionError" message="expected [true] but found [false]">
      <![CDATA[java.lang.AssertionError: expected [true] but found [false]
at org.testng.Assert.fail(Assert.java:96)
at org.testng.Assert.failNotEquals(Assert.java:776)
at org.testng.Assert.assertTrue(Assert.java:44)
at org.testng.Assert.assertTrue(Assert.java:54)
at com.qa.testcases.TestCswLogin.coverStoryOTPLogin(TestCswLogin.java:250)
at sun.reflect.NativeMethodAccessorImpl.invoke0(Native Method)
at sun.reflect.NativeMethodAccessorImpl.invoke(Unknown Source)
at sun.reflect.DelegatingMethodAccessorImpl.invoke(Unknown Source)
at java.lang.reflect.Method.invoke(Unknown Source)
at org.testng.internal.MethodInvocationHelper.invokeMethod(MethodInvocationHelper.java:124)
at org.testng.internal.Invoker.invokeMethod(Invoker.java:580)
at org.testng.internal.Invoker.invokeTestMethod(Invoker.java:716)
at org.testng.internal.Invoker.invokeTestMethods(Invoker.java:988)
at org.testng.internal.TestMethodWorker.invokeTestMethods(TestMethodWorker.java:125)
at org.testng.internal.TestMethodWorker.run(TestMethodWorker.java:109)
at org.testng.TestRunner.privateRun(TestRunner.java:648)
at org.testng.TestRunner.run(TestRunner.java:505)
at org.testng.SuiteRunner.runTest(SuiteRunner.java:455)
at org.testng.SuiteRunner.runSequentially(SuiteRunner.java:450)
at org.testng.SuiteRunner.privateRun(SuiteRunner.java:415)
at org.testng.SuiteRunner.run(SuiteRunner.java:364)
at org.testng.SuiteRunnerWorker.runSuite(SuiteRunnerWorker.java:52)
at org.testng.SuiteRunnerWorker.run(SuiteRunnerWorker.java:84)
at org.testng.TestNG.runSuitesSequentially(TestNG.java:1208)
at org.testng.TestNG.runSuitesLocally(TestNG.java:1137)
at org.testng.TestNG.runSuites(TestNG.java:1049)
at org.testng.TestNG.run(TestNG.java:1017)
at org.testng.remote.AbstractRemoteTestNG.run(AbstractRemoteTestNG.java:114)
at org.testng.remote.RemoteTestNG.initAndRun(RemoteTestNG.java:251)
at org.testng.remote.RemoteTestNG.main(RemoteTestNG.java:77)
]]>
    </failure>
  </testcase> <!-- coverStoryOTPLogin -->
  <testcase name="coverStoryPhoneLogin" time="0.0" classname="com.qa.testcases.TestCswLogin">
    <ignored/>
  </testcase> <!-- coverStoryPhoneLogin -->
  <testcase name="coverStorygoogleplusLogin" time="0.0" classname="com.qa.testcases.TestCswLogin">
    <ignored/>
  </testcase> <!-- coverStorygoogleplusLogin -->
  <testcase name="coverStoryEmailLogin" time="0.0" classname="com.qa.testcases.TestCswLogin">
    <ignored/>
  </testcase> <!-- coverStoryEmailLogin -->
  <testcase name="coverStoryFacebookLogin" time="0.0" classname="com.qa.testcases.TestCswLogin">
    <ignored/>
  </testcase> <!-- coverStoryFacebookLogin -->
</testsuite> <!-- Default test -->
